Workbook

Sheet Start Here
A1: Christmas Gift & Budget Tracker
A2: Pantry Printable Co. · Excel + Google Sheets · Made for one household, for personal use
B4: Open it
B5: Google Sheets: go to sheets.google.com, then File > Import > Upload and pick this file (or upload it to Google Drive, open it and choose File > Save as Google Sheets).
B6: Excel: double-click the file. If you see a yellow 'Protected View' bar, click Enable Editing.
B7: Tip: keep this file as your clean copy and use File > Save as (or Make a copy) for this year.
B8: Colors
B9: Cream cells: type here.
B10: White cells calculate by themselves. Please don't type over them (except the Gifts budget, see the Budget tab).
B11: Five steps
B12: 1. People: list everyone you're buying for, with a budget for each.
B13: 2. Gift Tracker: add gift ideas. Pick the person from the dropdown and type a price.
B14: 3. When you buy, wrap or give a gift, set Bought?, Wrapped? or Given? to Yes.
B15: 4. Budget: set a budget for food, decorations, cards and the rest; log those costs in the Expense Log.
... B25: Merry Christmas from Pantry Printable Co.

Sheet Dashboard
A1: Christmas Gift & Budget Tracker
A2: Your Christmas at a glance. Everything on this page fills in by itself.
A4: =IF(TODAY()>DATE(YEAR(TODAY()),12,25),DATE(YEAR(TODAY())+1,12,25),DATE(YEAR(TODAY()),12,25))-TODAY()
A6: Money | D6: Gifts
A7: Total budget | B7: =Budget!B20 | D7: People on your list | E7: =COUNTA(People!$A$6:$A$55)
A8: Spent so far | B8: =Budget!C20 | D8: Gifts on the list | E8: =COUNTA('Gift Tracker'!$B$5:$B$304)
A9: Left to spend | B9: =Budget!D20 | D9: Bought | E9: =COUNTIF('Gift Tracker'!$E$5:$E$304,"Yes") | F9: =IF(COUNTA('Gift Tracker'!$B$5:$B$304)=0,"",REPT("█",ROUND(MIN(1,MAX(0,E9/COUNTA('Gift Tracker'!$B$5:$B$304)))*20,0))&REPT("░",20-ROUND(MIN(1,MAX(0,E9/COUNTA('Gift Tracker'!$B$5:$B$304)))*20,0)))
A10: Budget used | B10: =Budget!E20 | D10: Wrapped | E10: =COUNTIF('Gift Tracker'!$F$5:$F$304,"Yes") | F10: =IF(COUNTA('Gift Tracker'!$B$5:$B$304)=0,"",REPT("█",ROUND(MIN(1,MAX(0,E10/COUNTA('Gift Tracker'!$B$5:$B$304)))*20,0))&REPT("░",20-ROUND(MIN(1,MAX(0,E10/COUNTA('Gift Tracker'!$B$5:$B$304)))*20,0)))
A11: =IF(B10="","",REPT("█",ROUND(MIN(1,MAX(0,B10))*20,0))&REPT("░",20-ROUND(MIN(1,MAX(0,B10))*20,0))) | D11: Given | E11: =COUNTIF('Gift Tracker'!$G$5:$G$304,"Yes") | F11: =IF(COUNTA('Gift Tracker'!$B$5:$B$304)=0,"",REPT("█",ROUND(MIN(1,MAX(0,E11/COUNTA('Gift Tracker'!$B$5:$B$304)))*20,0))&REPT("░",20-ROUND(MIN(1,MAX(0,E11/COUNTA('Gift Tracker'!$B$5:$B$304)))*20,0)))
D12: People over budget | E12: =COUNTIF(People!$K$6:$K$55,"Over budget")
A13: Savings
A14: Savings goal | B14: =IF(Savings!B4="","",Savings!B4) | D14: Spending by category
A15: Saved so far | B15: =Savings!D4 | D15: Category | E15: Spent | F15: of budget
A16: =IF(Savings!D6="","",REPT("█",ROUND(MIN(1,MAX(0,Savings!D6))*20,0))&REPT("░",20-ROUND(MIN(1,MAX(0,Savings!D6))*20,0))) | D16: =IF(Budget!A5="","",Budget!A5) | E16: =IF(Budget!A5="","",Budget!C5) | F16: =Budget!F5
D17: =IF(Budget!A6="","",Budget!A6) | E17: =IF(Budget!A6="","",Budget!C6) | F17: =Budget!F6
D18: =IF(Budget!A7="","",Budget!A7) | E18: =IF(Budget!A7="","",Budget!C7) | F18: =Budget!F7
A19: Checks | D19: =IF(Budget!A8="","",Budget!A8) | E19: =IF(Budget!A8="","",Budget!C8) | F19: =Budget!F8
A20: Expenses not in a category | B20: =Budget!C18 | D20: =IF(Budget!A9="","",Budget!A9) | E20: =IF(Budget!A9="","",Budget!C9) | F20: =Budget!F9
A21: Gifts for names not on People | B21: =COUNTA('Gift Tracker'!$A$5:$A$304)-People!G57 | D21: =IF(Budget!A10="","",Budget!A10) | E21: =IF(Budget!A10="","",Budget!C10) | F21: =Budget!F10
A22: Both should be 0. If not, check spelling on the Gift Tracker and Expense Log. | D22: =IF(Budget!A11="","",Budget!A11) | E22: =IF(Budget!A11="","",Budget!C11) | F22: =Budget!F11
D23: =IF(Budget!A12="","",Budget!A12) | E23: =IF(Budget!A12="","",Budget!C12) | F23: =Budget!F12
D24: =IF(Budget!A13="","",Budget!A13) | E24: =IF(Budget!A13="","",Budget!C13) | F24: =Budget!F13
D25: =IF(Budget!A14="","",Budget!A14) | E25: =IF(Budget!A14="","",Budget!C14) | F25: =Budget!F14
D26: =IF(Budget!A15="","",Budget!A15) | E26: =IF(Budget!A15="","",Budget!C15) | F26: =Budget!F15
D27: =IF(Budget!A16="","",Budget!A16) | E27: =IF(Budget!A16="","",Budget!C16) | F27: =Budget!F16
D28: =IF(Budget!A17="","",Budget!A17) | E28: =IF(Budget!A17="","",Budget!C17) | F28: =Budget!F17

Sheet Budget
A1: Holiday Budget by Category
A2: Type a budget per category. Spent fills in from the Gift Tracker (gifts) and the Expense Log (everything else).
A4: Category | B4: Budget | C4: Spent | D4: Left | E4: % used | F4: Progress
A5: Gifts (from Gift Tracker) | B5: =People!C57 | C5: =SUMIFS('Gift Tracker'!$D$5:$D$304,'Gift Tracker'!$E$5:$E$304,"Yes") | D5: =IF(A5="","",N(B5)-N(C5)) | E5: =IF(OR(A5="",N(B5)=0),"",N(C5)/B5) | F5: =IF(E5="","",REPT("█",ROUND(MIN(1,MAX(0,E5))*20,0))&REPT("░",20-ROUND(MIN(1,MAX(0,E5))*20,0)))
A6: Food & treats | B6: 250 | C6: =IF(A6="","",SUMIFS('Expense Log'!$D$5:$D$404,'Expense Log'!$C$5:$C$404,A6)) | D6: =IF(A6="","",N(B6)-N(C6)) | E6: =IF(OR(A6="",N(B6)=0),"",N(C6)/B6) | F6: =IF(E6="","",REPT("█",ROUND(MIN(1,MAX(0,E6))*20,0))&REPT("░",20-ROUND(MIN(1,MAX(0,E6))*20,0)))
A7: Decorations | B7: 80 | C7: =IF(A7="","",SUMIFS('Expense Log'!$D$5:$D$404,'Expense Log'!$C$5:$C$404,A7)) | D7: =IF(A7="","",N(B7)-N(C7)) | E7: =IF(OR(A7="",N(B7)=0),"",N(C7)/B7) | F7: =IF(E7="","",REPT("█",ROUND(MIN(1,MAX(0,E7))*20,0))&REPT("░",20-ROUND(MIN(1,MAX(0,E7))*20,0)))
A8: Wrapping & tags | B8: 30 | C8: =IF(A8="","",SUMIFS('Expense Log'!$D$5:$D$404,'Expense Log'!$C$5:$C$404,A8)) | D8: =IF(A8="","",N(B8)-N(C8)) | E8: =IF(OR(A8="",N(B8)=0),"",N(C8)/B8) | F8: =IF(E8="","",REPT("█",ROUND(MIN(1,MAX(0,E8))*20,0))&REPT("░",20-ROUND(MIN(1,MAX(0,E8))*20,0)))
A9: Cards & postage | B9: 40 | C9: =IF(A9="","",SUMIFS('Expense Log'!$D$5:$D$404,'Expense Log'!$C$5:$C$404,A9)) | D9: =IF(A9="","",N(B9)-N(C9)) | E9: =IF(OR(A9="",N(B9)=0),"",N(C9)/B9) | F9: =IF(E9="","",REPT("█",ROUND(MIN(1,MAX(0,E9))*20,0))&REPT("░",20-ROUND(MIN(1,MAX(0,E9))*20,0)))
A10: Parties & hosting | B10: 100 | C10: =IF(A10="","",SUMIFS('Expense Log'!$D$5:$D$404,'Expense Log'!$C$5:$C$404,A10)) | D10: =IF(A10="","",N(B10)-N(C10)) | E10: =IF(OR(A10="",N(B10)=0),"",N(C10)/B10) | F10: =IF(E10="","",REPT("█",ROUND(MIN(1,MAX(0,E10))*20,0))&REPT("░",20-ROUND(MIN(1,MAX(0,E10))*20,0)))
A11: Travel | B11: 200 | C11: =IF(A11="","",SUMIFS('Expense Log'!$D$5:$D$404,'Expense Log'!$C$5:$C$404,A11)) | D11: =IF(A11="","",N(B11)-N(C11)) | E11: =IF(OR(A11="",N(B11)=0),"",N(C11)/B11) | F11: =IF(E11="","",REPT("█",ROUND(MIN(1,MAX(0,E11))*20,0))&REPT("░",20-ROUND(MIN(1,MAX(0,E11))*20,0)))
A12: Outfits | B12: 60 | C12: =IF(A12="","",SUMIFS('Expense Log'!$D$5:$D$404,'Expense Log'!$C$5:$C$404,A12)) | D12: =IF(A12="","",N(B12)-N(C12)) | E12: =IF(OR(A12="",N(B12)=0),"",N(C12)/B12) | F12: =IF(E12="","",REPT("█",ROUND(MIN(1,MAX(0,E12))*20,0))&REPT("░",20-ROUND(MIN(1,MAX(0,E12))*20,0)))
A13: Charity & giving | B13: 50 | C13: =IF(A13="","",SUMIFS('Expense Log'!$D$5:$D$404,'Expense Log'!$C$5:$C$404,A13)) | D13: =IF(A13="","",N(B13)-N(C13)) | E13: =IF(OR(A13="",N(B13)=0),"",N(C13)/B13) | F13: =IF(E13="","",REPT("█",ROUND(MIN(1,MAX(0,E13))*20,0))&REPT("░",20-ROUND(MIN(1,MAX(0,E13))*20,0)))
A14: Kids' activities | B14: 40 | C14: =IF(A14="","",SUMIFS('Expense Log'!$D$5:$D$404,'Expense Log'!$C$5:$C$404,A14)) | D14: =IF(A14="","",N(B14)-N(C14)) | E14: =IF(OR(A14="",N(B14)=0),"",N(C14)/B14) | F14: =IF(E14="","",REPT("█",ROUND(MIN(1,MAX(0,E14))*20,0))&REPT("░",20-ROUND(MIN(1,MAX(0,E14))*20,0)))
A15: Other | B15: 30 | C15: =IF(A15="","",SUMIFS('Expense Log'!$D$5:$D$404,'Expense Log'!$C$5:$C$404,A15)) | D15: =IF(A15="","",N(B15)-N(C15)) | E15: =IF(OR(A15="",N(B15)=0),"",N(C15)/B15) | F15: =IF(E15="","",REPT("█",ROUND(MIN(1,MAX(0,E15))*20,0))&REPT("░",20-ROUND(MIN(1,MAX(0,E15))*20,0)))
C16: =IF(A16="","",SUMIFS('Expense Log'!$D$5:$D$404,'Expense Log'!$C$5:$C$404,A16)) | D16: =IF(A16="","",N(B16)-N(C16)) | E16: =IF(OR(A16="",N(B16)=0),"",N(C16)/B16) | F16: =IF(E16="","",REPT("█",ROUND(MIN(1,MAX(0,E16))*20,0))&REPT("░",20-ROUND(MIN(1,MAX(0,E16))*20,0)))
C17: =IF(A17="","",SUMIFS('Expense Log'!$D$5:$D$404,'Expense Log'!$C$5:$C$404,A17)) | D17: =IF(A17="","",N(B17)-N(C17)) | E17: =IF(OR(A17="",N(B17)=0),"",N(C17)/B17) | F17: =IF(E17="","",REPT("█",ROUND(MIN(1,MAX(0,E17))*20,0))&REPT("░",20-ROUND(MIN(1,MAX(0,E17))*20,0)))
A18: Not in a category | C18: =SUM('Expense Log'!$D$5:$D$404)-SUM(C6:C17)
A20: TOTAL | B20: =SUM(B5:B17) | C20: =SUM(C5:C18) | D20: =B20-C20 | E20: =IF(B20=0,"",C20/B20) | F20: =IF(E20="","",REPT("█",ROUND(MIN(1,MAX(0,E20))*20,0))&REPT("░",20-ROUND(MIN(1,MAX(0,E20))*20,0)))
A22: Tip: the Gifts budget adds up the budgets on the People tab. Type over it if you prefer one number. Rename any category (or use the empty cream rows); the Expense Log dropdown follows.

Sheet People
A1: Gift Budget by Person
A2: One row per person. Type a name, group and budget; the rest fills in from the Gift Tracker.
A5: Name | B5: Group | C5: Budget | D5: Planned (all gifts) | E5: Spent (bought) | F5: Left | G5: Gifts | H5: Bought | I5: Wrapped | J5: Given | K5: Status
A6: Mom | B6: Family | C6: 120 | D6: =IF($A6="","",SUMIFS('Gift Tracker'!$D$5:$D$304,'Gift Tracker'!$A$5:$A$304,$A6)) | E6: =IF($A6="","",SUMIFS('Gift Tracker'!$D$5:$D$304,'Gift Tracker'!$A$5:$A$304,$A6,'Gift Tracker'!$E$5:$E$304,"Yes")) | F6: =IF(OR($A6="",C6=""),"",C6-E6) | G6: =IF($A6="","",COUNTIF('Gift Tracker'!$A$5:$A$304,$A6)) | H6: =IF($A6="","",COUNTIFS('Gift Tracker'!$A$5:$A$304,$A6,'Gift Tracker'!$E$5:$E$304,"Yes")) | I6: =IF($A6="","",COUNTIFS('Gift Tracker'!$A$5:$A$304,$A6,'Gift Tracker'!$F$5:$F$304,"Yes")) | J6: =IF($A6="","",COUNTIFS('Gift Tracker'!$A$5:$A$304,$A6,'Gift Tracker'!$G$5:$G$304,"Yes")) | K6: =IF($A6="","",IF(G6=0,"No gift yet",IF(AND(C6<>"",E6>C6),"Over budget",IF(AND(C6<>"",D6>C6,J6<G6),"Plan over budget",IF(J6=G6,"All given ✓",IF(H6<G6,"Shopping",IF(I6<G6,"To wrap","Ready to give")))))))
A7: Dad | B7: Family | C7: 120 | D7: =IF($A7="","",SUMIFS('Gift Tracker'!$D$5:$D$304,'Gift Tracker'!$A$5:$A$304,$A7)) | E7: =IF($A7="","",SUMIFS('Gift Tracker'!$D$5:$D$304,'Gift Tracker'!$A$5:$A$304,$A7,'Gift Tracker'!$E$5:$E$304,"Yes")) | F7: =IF(OR($A7="",C7=""),"",C7-E7) | G7: =IF($A7="","",COUNTIF('Gift Tracker'!$A$5:$A$304,$A7)) | H7: =IF($A7="","",COUNTIFS('Gift Tracker'!$A$5:$A$304,$A7,'Gift Tracker'!$E$5:$E$304,"Yes")) | I7: =IF($A7="","",COUNTIFS('Gift Tracker'!$A$5:$A$304,$A7,'Gift Tracker'!$F$5:$F$304,"Yes")) | J7: =IF($A7="","",COUNTIFS('Gift Tracker'!$A$5:$A$304,$A7,'Gift Tracker'!$G$5:$G$304,"Yes")) | K7: =IF($A7="","",IF(G7=0,"No gift yet",IF(AND(C7<>"",E7>C7),"Over budget",IF(AND(C7<>"",D7>C7,J7<G7),"Plan over budget",IF(J7=G7,"All given ✓",IF(H7<G7,"Shopping",IF(I7<G7,"To wrap","Ready to give")))))))
A8: Emma | B8: Kids | C8: 150 | D8: =IF($A8="","",SUMIFS('Gift Tracker'!$D$5:$D$304,'Gift Tracker'!$A$5:$A$304,$A8)) | E8: =IF($A8="","",SUMIFS('Gift Tracker'!$D$5:$D$304,'Gift Tracker'!$A$5:$A$304,$A8,'Gift Tracker'!$E$5:$E$304,"Yes")) | F8: =IF(OR($A8="",C8=""),"",C8-E8) | G8: =IF($A8="","",COUNTIF('Gift Tracker'!$A$5:$A$304,$A8)) | H8: =IF($A8="","",COUNTIFS('Gift Tracker'!$A$5:$A$304,$A8,'Gift Tracker'!$E$5:$E$304,"Yes")) | I8: =IF($A8="","",COUNTIFS('Gift Tracker'!$A$5:$A$304,$A8,'Gift Tracker'!$F$5:$F$304,"Yes")) | J8: =IF($A8="","",COUNTIFS('Gift Tracker'!$A$5:$A$304,$A8,'Gift Tracker'!$G$5:$G$304,"Yes")) | K8: =IF($A8="","",IF(G8=0,"No gift yet",IF(AND(C8<>"",E8>C8),"Over budget",IF(AND(C8<>"",D8>C8,J8<G8),"Plan over budget",IF(J8=G8,"All given ✓",IF(H8<G8,"Shopping",IF(I8<G8,"To wrap","Ready to give")))))))
A9: Leo | B9: Kids | C9: 150 | D9: =IF($A9="","",SUMIFS('Gift Tracker'!$D$5:$D$304,'Gift Tracker'!$A$5:$A$304,$A9)) | E9: =IF($A9="","",SUMIFS('Gift Tracker'!$D$5:$D$304,'Gift Tracker'!$A$5:$A$304,$A9,'Gift Tracker'!$E$5:$E$304,"Yes")) | F9: =IF(OR($A9="",C9=""),"",C9-E9) | G9: =IF($A9="","",COUNTIF('Gift Tracker'!$A$5:$A$304,$A9)) | H9: =IF($A9="","",COUNTIFS('Gift Tracker'!$A$5:$A$304,$A9,'Gift Tracker'!$E$5:$E$304,"Yes")) | I9: =IF($A9="","",COUNTIFS('Gift Tracker'!$A$5:$A$304,$A9,'Gift Tracker'!$F$5:$F$304,"Yes")) | J9: =IF($A9="","",COUNTIFS('Gift Tracker'!$A$5:$A$304,$A9,'Gift Tracker'!$G$5:$G$304,"Yes")) | K9: =IF($A9="","",IF(G9=0,"No gift yet",IF(AND(C9<>"",E9>C9),"Over budget",IF(AND(C9<>"",D9>C9,J9<G9),"Plan over budget",IF(J9=G9,"All given ✓",IF(H9<G9,"Shopping",IF(I9<G9,"To wrap","Ready to give")))))))
A10: Grandma Jo | B10: Family | C10: 60 | D10: =IF($A10="","",SUMIFS('Gift Tracker'!$D$5:$D$304,'Gift Tracker'!$A$5:$A$304,$A10)) | E10: =IF($A10="","",SUMIFS('Gift Tracker'!$D$5:$D$304,'Gift Tracker'!$A$5:$A$304,$A10,'Gift Tracker'!$E$5:$E$304,"Yes")) | F10: =IF(OR($A10="",C10=""),"",C10-E10) | G10: =IF($A10="","",COUNTIF('Gift Tracker'!$A$5:$A$304,$A10)) | H10: =IF($A10="","",COUNTIFS('Gift Tracker'!$A$5:$A$304,$A10,'Gift Tracker'!$E$5:$E$304,"Yes")) | I10: =IF($A10="","",COUNTIFS('Gift Tracker'!$A$5:$A$304,$A10,'Gift Tracker'!$F$5:$F$304,"Yes")) | J10: =IF($A10="","",COUNTIFS('Gift Tracker'!$A$5:$A$304,$A10,'Gift Tracker'!$G$5:$G$304,"Yes")) | K10: =IF($A10="","",IF(G10=0,"No gift yet",IF(AND(C10<>"",E10>C10),"Over budget",IF(AND(C10<>"",D10>C10,J10<G10),"Plan over budget",IF(J10=G10,"All given ✓",IF(H10<G10,"Shopping",IF(I10<G10,"To wrap","Ready to give")))))))
A11: Aunt Sara | B11: Family | C11: 40 | D11: =IF($A11="","",SUMIFS('Gift Tracker'!$D$5:$D$304,'Gift Tracker'!$A$5:$A$304,$A11)) | E11: =IF($A11="","",SUMIFS('Gift Tracker'!$D$5:$D$304,'Gift Tracker'!$A$5:$A$304,$A11,'Gift Tracker'!$E$5:$E$304,"Yes")) | F11: =IF(OR($A11="",C11=""),"",C11-E11) | G11: =IF($A11="","",COUNTIF('Gift Tracker'!$A$5:$A$304,$A11)) | H11: =IF($A11="","",COUNTIFS('Gift Tracker'!$A$5:$A$304,$A11,'Gift Tracker'!$E$5:$E$304,"Yes")) | I11: =IF($A11="","",COUNTIFS('Gift Tracker'!$A$5:$A$304,$A11,'Gift Tracker'!$F$5:$F$304,"Yes")) | J11: =IF($A11="","",COUNTIFS('Gift Tracker'!$A$5:$A$304,$A11,'Gift Tracker'!$G$5:$G$304,"Yes")) | K11: =IF($A11="","",IF(G11=0,"No gift yet",IF(AND(C11<>"",E11>C11),"Over budget",IF(AND(C11<>"",D11>C11,J11<G11),"Plan over budget",IF(J11=G11,"All given ✓",IF(H11<G11,"Shopping",IF(I11<G11,"To wrap","Ready to give")))))))
A12: Sam (Secret Santa) | B12: Work | C12: 25 | D12: =IF($A12="","",SUMIFS('Gift Tracker'!$D$5:$D$304,'Gift Tracker'!$A$5:$A$304,$A12)) | E12: =IF($A12="","",SUMIFS('Gift Tracker'!$D$5:$D$304,'Gift Tracker'!$A$5:$A$304,$A12,'Gift Tracker'!$E$5:$E$304,"Yes")) | F12: =IF(OR($A12="",C12=""),"",C12-E12) | G12: =IF($A12="","",COUNTIF('Gift Tracker'!$A$5:$A$304,$A12)) | H12: =IF($A12="","",COUNTIFS('Gift Tracker'!$A$5:$A$304,$A12,'Gift Tracker'!$E$5:$E$304,"Yes")) | I12: =IF($A12="","",COUNTIFS('Gift Tracker'!$A$5:$A$304,$A12,'Gift Tracker'!$F$5:$F$304,"Yes")) | J12: =IF($A12="","",COUNTIFS('Gift Tracker'!$A$5:$A$304,$A12,'Gift Tracker'!$G$5:$G$304,"Yes")) | K12: =IF($A12="","",IF(G12=0,"No gift yet",IF(AND(C12<>"",E12>C12),"Over budget",IF(AND(C12<>"",D12>C12,J12<G12),"Plan over budget",IF(J12=G12,"All given ✓",IF(H12<G12,"Shopping",IF(I12<G12,"To wrap","Ready to give")))))))
A13: Ms. Rivera (teacher) | B13: School | C13: 20 | D13: =IF($A13="","",SUMIFS('Gift Tracker'!$D$5:$D$304,'Gift Tracker'!$A$5:$A$304,$A13)) | E13: =IF($A13="","",SUMIFS('Gift Tracker'!$D$5:$D$304,'Gift Tracker'!$A$5:$A$304,$A13,'Gift Tracker'!$E$5:$E$304,"Yes")) | F13: =IF(OR($A13="",C13=""),"",C13-E13) | G13: =IF($A13="","",COUNTIF('Gift Tracker'!$A$5:$A$304,$A13)) | H13: =IF($A13="","",COUNTIFS('Gift Tracker'!$A$5:$A$304,$A13,'Gift Tracker'!$E$5:$E$304,"Yes")) | I13: =IF($A13="","",COUNTIFS('Gift Tracker'!$A$5:$A$304,$A13,'Gift Tracker'!$F$5:$F$304,"Yes")) | J13: =IF($A13="","",COUNTIFS('Gift Tracker'!$A$5:$A$304,$A13,'Gift Tracker'!$G$5:$G$304,"Yes")) | K13: =IF($A13="","",IF(G13=0,"No gift yet",IF(AND(C13<>"",E13>C13),"Over budget",IF(AND(C13<>"",D13>C13,J13<G13),"Plan over budget",IF(J13=G13,"All given ✓",IF(H13<G13,"Shopping",IF(I13<G13,"To wrap","Ready to give")))))))
A14: Neighbors | B14: Neighbors | C14: 30 | D14: =IF($A14="","",SUMIFS('Gift Tracker'!$D$5:$D$304,'Gift Tracker'!$A$5:$A$304,$A14)) | E14: =IF($A14="","",SUMIFS('Gift Tracker'!$D$5:$D$304,'Gift Tracker'!$A$5:$A$304,$A14,'Gift Tracker'!$E$5:$E$304,"Yes")) | F14: =IF(OR($A14="",C14=""),"",C14-E14) | G14: =IF($A14="","",COUNTIF('Gift Tracker'!$A$5:$A$304,$A14)) | H14: =IF($A14="","",COUNTIFS('Gift Tracker'!$A$5:$A$304,$A14,'Gift Tracker'!$E$5:$E$304,"Yes")) | I14: =IF($A14="","",COUNTIFS('Gift Tracker'!$A$5:$A$304,$A14,'Gift Tracker'!$F$5:$F$304,"Yes")) | J14: =IF($A14="","",COUNTIFS('Gift Tracker'!$A$5:$A$304,$A14,'Gift Tracker'!$G$5:$G$304,"Yes")) | K14: =IF($A14="","",IF(G14=0,"No gift yet",IF(AND(C14<>"",E14>C14),"Over budget",IF(AND(C14<>"",D14>C14,J14<G14),"Plan over budget",IF(J14=G14,"All given ✓",IF(H14<G14,"Shopping",IF(I14<G14,"To wrap","Ready to give")))))))
A15: Best friend Kim | B15: Friends | C15: 50 | D15: =IF($A15="","",SUMIFS('Gift Tracker'!$D$5:$D$304,'Gift Tracker'!$A$5:$A$304,$A15)) | E15: =IF($A15="","",SUMIFS('Gift Tracker'!$D$5:$D$304,'Gift Tracker'!$A$5:$A$304,$A15,'Gift Tracker'!$E$5:$E$304,"Yes")) | F15: =IF(OR($A15="",C15=""),"",C15-E15) | G15: =IF($A15="","",COUNTIF('Gift Tracker'!$A$5:$A$304,$A15)) | H15: =IF($A15="","",COUNTIFS('Gift Tracker'!$A$5:$A$304,$A15,'Gift Tracker'!$E$5:$E$304,"Yes")) | I15: =IF($A15="","",COUNTIFS('Gift Tracker'!$A$5:$A$304,$A15,'Gift Tracker'!$F$5:$F$304,"Yes")) | J15: =IF($A15="","",COUNTIFS('Gift Tracker'!$A$5:$A$304,$A15,'Gift Tracker'!$G$5:$G$304,"Yes")) | K15: =IF($A15="","",IF(G15=0,"No gift yet",IF(AND(C15<>"",E15>C15),"Over budget",IF(AND(C15<>"",D15>C15,J15<G15),"Plan over budget",IF(J15=G15,"All given ✓",IF(H15<G15,"Shopping",IF(I15<G15,"To wrap","Ready to give")))))))
D16: =IF($A16="","",SUMIFS('Gift Tracker'!$D$5:$D$304,'Gift Tracker'!$A$5:$A$304,$A16)) | E16: =IF($A16="","",SUMIFS('Gift Tracker'!$D$5:$D$304,'Gift Tracker'!$A$5:$A$304,$A16,'Gift Tracker'!$E$5:$E$304,"Yes")) | F16: =IF(OR($A16="",C16=""),"",C16-E16) | G16: =IF($A16="","",COUNTIF('Gift Tracker'!$A$5:$A$304,$A16)) | H16: =IF($A16="","",COUNTIFS('Gift Tracker'!$A$5:$A$304,$A16,'Gift Tracker'!$E$5:$E$304,"Yes")) | I16: =IF($A16="","",COUNTIFS('Gift Tracker'!$A$5:$A$304,$A16,'Gift Tracker'!$F$5:$F$304,"Yes")) | J16: =IF($A16="","",COUNTIFS('Gift Tracker'!$A$5:$A$304,$A16,'Gift Tracker'!$G$5:$G$304,"Yes")) | K16: =IF($A16="","",IF(G16=0,"No gift yet",IF(AND(C16<>"",E16>C16),"Over budget",IF(AND(C16<>"",D16>C16,J16<G16),"Plan over budget",IF(J16=G16,"All given ✓",IF(H16<G16,"Shopping",IF(I16<G16,"To wrap","Ready to give")))))))
D17: =IF($A17="","",SUMIFS('Gift Tracker'!$D$5:$D$304,'Gift Tracker'!$A$5:$A$304,$A17)) | E17: =IF($A17="","",SUMIFS('Gift Tracker'!$D$5:$D$304,'Gift Tracker'!$A$5:$A$304,$A17,'Gift Tracker'!$E$5:$E$304,"Yes")) | F17: =IF(OR($A17="",C17=""),"",C17-E17) | G17: =IF($A17="","",COUNTIF('Gift Tracker'!$A$5:$A$304,$A17)) | H17: =IF($A17="","",COUNTIFS('Gift Tracker'!$A$5:$A$304,$A17,'Gift Tracker'!$E$5:$E$304,"Yes")) | I17: =IF($A17="","",COUNTIFS('Gift Tracker'!$A$5:$A$304,$A17,'Gift Tracker'!$F$5:$F$304,"Yes")) | J17: =IF($A17="","",COUNTIFS('Gift Tracker'!$A$5:$A$304,$A17,'Gift Tracker'!$G$5:$G$304,"Yes")) | K17: =IF($A17="","",IF(G17=0,"No gift yet",IF(AND(C17<>"",E17>C17),"Over budget",IF(AND(C17<>"",D17>C17,J17<G17),"Plan over budget",IF(J17=G17,"All given ✓",IF(H17<G17,"Shopping",IF(I17<G17,"To wrap","Ready to give")))))))
D18: =IF($A18="","",SUMIFS('Gift Tracker'!$D$5:$D$304,'Gift Tracker'!$A$5:$A$304,$A18)) | E18: =IF($A18="","",SUMIFS('Gift Tracker'!$D$5:$D$304,'Gift Tracker'!$A$5:$A$304,$A18,'Gift Tracker'!$E$5:$E$304,"Yes")) | F18: =IF(OR($A18="",C18=""),"",C18-E18) | G18: =IF($A18="","",COUNTIF('Gift Tracker'!$A$5:$A$304,$A18)) | H18: =IF($A18="","",COUNTIFS('Gift Tracker'!$A$5:$A$304,$A18,'Gift Tracker'!$E$5:$E$304,"Yes")) | I18: =IF($A18="","",COUNTIFS('Gift Tracker'!$A$5:$A$304,$A18,'Gift Tracker'!$F$5:$F$304,"Yes")) | J18: =IF($A18="","",COUNTIFS('Gift Tracker'!$A$5:$A$304,$A18,'Gift Tracker'!$G$5:$G$304,"Yes")) | K18: =IF($A18="","",IF(G18=0,"No gift yet",IF(AND(C18<>"",E18>C18),"Over budget",IF(AND(C18<>"",D18>C18,J18<G18),"Plan over budget",IF(J18=G18,"All given ✓",IF(H18<G18,"Shopping",IF(I18<G18,"To wrap","Ready to give")))))))
D19: =IF($A19="","",SUMIFS('Gift Tracker'!$D$5:$D$304,'Gift Tracker'!$A$5:$A$304,$A19)) | E19: =IF($A19="","",SUMIFS('Gift Tracker'!$D$5:$D$304,'Gift Tracker'!$A$5:$A$304,$A19,'Gift Tracker'!$E$5:$E$304,"Yes")) | F19: =IF(OR($A19="",C19=""),"",C19-E19) | G19: =IF($A19="","",COUNTIF('Gift Tracker'!$A$5:$A$304,$A19)) | H19: =IF($A19="","",COUNTIFS('Gift Tracker'!$A$5:$A$304,$A19,'Gift Tracker'!$E$5:$E$304,"Yes")) | I19: =IF($A19="","",COUNTIFS('Gift Tracker'!$A$5:$A$304,$A19,'Gift Tracker'!$F$5:$F$304,"Yes")) | J19: =IF($A19="","",COUNTIFS('Gift Tracker'!$A$5:$A$304,$A19,'Gift Tracker'!$G$5:$G$304,"Yes")) | K19: =IF($A19="","",IF(G19=0,"No gift yet",IF(AND(C19<>"",E19>C19),"Over budget",IF(AND(C19<>"",D19>C19,J19<G19),"Plan over budget",IF(J19=G19,"All given ✓",IF(H19<G19,"Shopping",IF(I19<G19,"To wrap","Ready to give")))))))
D20: =IF($A20="","",SUMIFS('Gift Tracker'!$D$5:$D$304,'Gift Tracker'!$A$5:$A$304,$A20)) | E20: =IF($A20="","",SUMIFS('Gift Tracker'!$D$5:$D$304,'Gift Tracker'!$A$5:$A$304,$A20,'Gift Tracker'!$E$5:$E$304,"Yes")) | F20: =IF(OR($A20="",C20=""),"",C20-E20) | G20: =IF($A20="","",COUNTIF('Gift Tracker'!$A$5:$A$304,$A20)) | H20: =IF($A20="","",COUNTIFS('Gift Tracker'!$A$5:$A$304,$A20,'Gift Tracker'!$E$5:$E$304,"Yes")) | I20: =IF($A20="","",COUNTIFS('Gift Tracker'!$A$5:$A$304,$A20,'Gift Tracker'!$F$5:$F$304,"Yes")) | J20: =IF($A20="","",COUNTIFS('Gift Tracker'!$A$5:$A$304,$A20,'Gift Tracker'!$G$5:$G$304,"Yes")) | K20: =IF($A20="","",IF(G20=0,"No gift yet",IF(AND(C20<>"",E20>C20),"Over budget",IF(AND(C20<>"",D20>C20,J20<G20),"Plan over budget",IF(J20=G20,"All given ✓",IF(H20<G20,"Shopping",IF(I20<G20,"To wrap","Ready to give")))))))
D21: =IF($A21="","",SUMIFS('Gift Tracker'!$D$5:$D$304,'Gift Tracker'!$A$5:$A$304,$A21)) | E21: =IF($A21="","",SUMIFS('Gift Tracker'!$D$5:$D$304,'Gift Tracker'!$A$5:$A$304,$A21,'Gift Tracker'!$E$5:$E$304,"Yes")) | F21: =IF(OR($A21="",C21=""),"",C21-E21) | G21: =IF($A21="","",COUNTIF('Gift Tracker'!$A$5:$A$304,$A21)) | H21: =IF($A21="","",COUNTIFS('Gift Tracker'!$A$5:$A$304,$A21,'Gift Tracker'!$E$5:$E$304,"Yes")) | I21: =IF($A21="","",COUNTIFS('Gift Tracker'!$A$5:$A$304,$A21,'Gift Tracker'!$F$5:$F$304,"Yes")) | J21: =IF($A21="","",COUNTIFS('Gift Tracker'!$A$5:$A$304,$A21,'Gift Tracker'!$G$5:$G$304,"Yes")) | K21: =IF($A21="","",IF(G21=0,"No gift yet",IF(AND(C21<>"",E21>C21),"Over budget",IF(AND(C21<>"",D21>C21,J21<G21),"Plan over budget",IF(J21=G21,"All given ✓",IF(H21<G21,"Shopping",IF(I21<G21,"To wrap","Ready to give")))))))
D22: =IF($A22="","",SUMIFS('Gift Tracker'!$D$5:$D$304,'Gift Tracker'!$A$5:$A$304,$A22)) | E22: =IF($A22="","",SUMIFS('Gift Tracker'!$D$5:$D$304,'Gift Tracker'!$A$5:$A$304,$A22,'Gift Tracker'!$E$5:$E$304,"Yes")) | F22: =IF(OR($A22="",C22=""),"",C22-E22) | G22: =IF($A22="","",COUNTIF('Gift Tracker'!$A$5:$A$304,$A22)) | H22: =IF($A22="","",COUNTIFS('Gift Tracker'!$A$5:$A$304,$A22,'Gift Tracker'!$E$5:$E$304,"Yes")) | I22: =IF($A22="","",COUNTIFS('Gift Tracker'!$A$5:$A$304,$A22,'Gift Tracker'!$F$5:$F$304,"Yes")) | J22: =IF($A22="","",COUNTIFS('Gift Tracker'!$A$5:$A$304,$A22,'Gift Tracker'!$G$5:$G$304,"Yes")) | K22: =IF($A22="","",IF(G22=0,"No gift yet",IF(AND(C22<>"",E22>C22),"Over budget",IF(AND(C22<>"",D22>C22,J22<G22),"Plan over budget",IF(J22=G22,"All given ✓",IF(H22<G22,"Shopping",IF(I22<G22,"To wrap","Ready to give")))))))
D23: =IF($A23="","",SUMIFS('Gift Tracker'!$D$5:$D$304,'Gift Tracker'!$A$5:$A$304,$A23)) | E23: =IF($A23="","",SUMIFS('Gift Tracker'!$D$5:$D$304,'Gift Tracker'!$A$5:$A$304,$A23,'Gift Tracker'!$E$5:$E$304,"Yes")) | F23: =IF(OR($A23="",C23=""),"",C23-E23) | G23: =IF($A23="","",COUNTIF('Gift Tracker'!$A$5:$A$304,$A23)) | H23: =IF($A23="","",COUNTIFS('Gift Tracker'!$A$5:$A$304,$A23,'Gift Tracker'!$E$5:$E$304,"Yes")) | I23: =IF($A23="","",COUNTIFS('Gift Tracker'!$A$5:$A$304,$A23,'Gift Tracker'!$F$5:$F$304,"Yes")) | J23: =IF($A23="","",COUNTIFS('Gift Tracker'!$A$5:$A$304,$A23,'Gift Tracker'!$G$5:$G$304,"Yes")) | K23: =IF($A23="","",IF(G23=0,"No gift yet",IF(AND(C23<>"",E23>C23),"Over budget",IF(AND(C23<>"",D23>C23,J23<G23),"Plan over budget",IF(J23=G23,"All given ✓",IF(H23<G23,"Shopping",IF(I23<G23,"To wrap","Ready to give")))))))
D24: =IF($A24="","",SUMIFS('Gift Tracker'!$D$5:$D$304,'Gift Tracker'!$A$5:$A$304,$A24)) | E24: =IF($A24="","",SUMIFS('Gift Tracker'!$D$5:$D$304,'Gift Tracker'!$A$5:$A$304,$A24,'Gift Tracker'!$E$5:$E$304,"Yes")) | F24: =IF(OR($A24="",C24=""),"",C24-E24) | G24: =IF($A24="","",COUNTIF('Gift Tracker'!$A$5:$A$304,$A24)) | H24: =IF($A24="","",COUNTIFS('Gift Tracker'!$A$5:$A$304,$A24,'Gift Tracker'!$E$5:$E$304,"Yes")) | I24: =IF($A24="","",COUNTIFS('Gift Tracker'!$A$5:$A$304,$A24,'Gift Tracker'!$F$5:$F$304,"Yes")) | J24: =IF($A24="","",COUNTIFS('Gift Tracker'!$A$5:$A$304,$A24,'Gift Tracker'!$G$5:$G$304,"Yes")) | K24: =IF($A24="","",IF(G24=0,"No gift yet",IF(AND(C24<>"",E24>C24),"Over budget",IF(AND(C24<>"",D24>C24,J24<G24),"Plan over budget",IF(J24=G24,"All given ✓",IF(H24<G24,"Shopping",IF(I24<G24,"To wrap","Ready to give")))))))
D25: =IF($A25="","",SUMIFS('Gift Tracker'!$D$5:$D$304,'Gift Tracker'!$A$5:$A$304,$A25)) | E25: =IF($A25="","",SUMIFS('Gift Tracker'!$D$5:$D$304,'Gift Tracker'!$A$5:$A$304,$A25,'Gift Tracker'!$E$5:$E$304,"Yes")) | F25: =IF(OR($A25="",C25=""),"",C25-E25) | G25: =IF($A25="","",COUNTIF('Gift Tracker'!$A$5:$A$304,$A25)) | H25: =IF($A25="","",COUNTIFS('Gift Tracker'!$A$5:$A$304,$A25,'Gift Tracker'!$E$5:$E$304,"Yes")) | I25: =IF($A25="","",COUNTIFS('Gift Tracker'!$A$5:$A$304,$A25,'Gift Tracker'!$F$5:$F$304,"Yes")) | J25: =IF($A25="","",COUNTIFS('Gift Tracker'!$A$5:$A$304,$A25,'Gift Tracker'!$G$5:$G$304,"Yes")) | K25: =IF($A25="","",IF(G25=0,"No gift yet",IF(AND(C25<>"",E25>C25),"Over budget",IF(AND(C25<>"",D25>C25,J25<G25),"Plan over budget",IF(J25=G25,"All given ✓",IF(H25<G25,"Shopping",IF(I25<G25,"To wrap","Ready to give")))))))
D26: =IF($A26="","",SUMIFS('Gift Tracker'!$D$5:$D$304,'Gift Tracker'!$A$5:$A$304,$A26)) | E26: =IF($A26="","",SUMIFS('Gift Tracker'!$D$5:$D$304,'Gift Tracker'!$A$5:$A$304,$A26,'Gift Tracker'!$E$5:$E$304,"Yes")) | F26: =IF(OR($A26="",C26=""),"",C26-E26) | G26: =IF($A26="","",COUNTIF('Gift Tracker'!$A$5:$A$304,$A26)) | H26: =IF($A26="","",COUNTIFS('Gift Tracker'!$A$5:$A$304,$A26,'Gift Tracker'!$E$5:$E$304,"Yes")) | I26: =IF($A26="","",COUNTIFS('Gift Tracker'!$A$5:$A$304,$A26,'Gift Tracker'!$F$5:$F$304,"Yes")) | J26: =IF($A26="","",COUNTIFS('Gift Tracker'!$A$5:$A$304,$A26,'Gift Tracker'!$G$5:$G$304,"Yes")) | K26: =IF($A26="","",IF(G26=0,"No gift yet",IF(AND(C26<>"",E26>C26),"Over budget",IF(AND(C26<>"",D26>C26,J26<G26),"Plan over budget",IF(J26=G26,"All given ✓",IF(H26<G26,"Shopping",IF(I26<G26,"To wrap","Ready to give")))))))
D27: =IF($A27="","",SUMIFS('Gift Tracker'!$D$5:$D$304,'Gift Tracker'!$A$5:$A$304,$A27)) | E27: =IF($A27="","",SUMIFS('Gift Tracker'!$D$5:$D$304,'Gift Tracker'!$A$5:$A$304,$A27,'Gift Tracker'!$E$5:$E$304,"Yes")) | F27: =IF(OR($A27="",C27=""),"",C27-E27) | G27: =IF($A27="","",COUNTIF('Gift Tracker'!$A$5:$A$304,$A27)) | H27: =IF($A27="","",COUNTIFS('Gift Tracker'!$A$5:$A$304,$A27,'Gift Tracker'!$E$5:$E$304,"Yes")) | I27: =IF($A27="","",COUNTIFS('Gift Tracker'!$A$5:$A$304,$A27,'Gift Tracker'!$F$5:$F$304,"Yes")) | J27: =IF($A27="","",COUNTIFS('Gift Tracker'!$A$5:$A$304,$A27,'Gift Tracker'!$G$5:$G$304,"Yes")) | K27: =IF($A27="","",IF(G27=0,"No gift yet",IF(AND(C27<>"",E27>C27),"Over budget",IF(AND(C27<>"",D27>C27,J27<G27),"Plan over budget",IF(J27=G27,"All given ✓",IF(H27<G27,"Shopping",IF(I27<G27,"To wrap","Ready to give")))))))
... D55: =IF($A55="","",SUMIFS('Gift Tracker'!$D$5:$D$304,'Gift Tracker'!$A$5:$A$304,$A55)) | E55: =IF($A55="","",SUMIFS('Gift Tracker'!$D$5:$D$304,'Gift Tracker'!$A$5:$A$304,$A55,'Gift Tracker'!$E$5:$E$304,"Yes")) | F55: =IF(OR($A55="",C55=""),"",C55-E55) | G55: =IF($A55="","",COUNTIF('Gift Tracker'!$A$5:$A$304,$A55)) | H55: =IF($A55="","",COUNTIFS('Gift Tracker'!$A$5:$A$304,$A55,'Gift Tracker'!$E$5:$E$304,"Yes")) | I55: =IF($A55="","",COUNTIFS('Gift Tracker'!$A$5:$A$304,$A55,'Gift Tracker'!$F$5:$F$304,"Yes")) | J55: =IF($A55="","",COUNTIFS('Gift Tracker'!$A$5:$A$304,$A55,'Gift Tracker'!$G$5:$G$304,"Yes")) | K55: =IF($A55="","",IF(G55=0,"No gift yet",IF(AND(C55<>"",E55>C55),"Over budget",IF(AND(C55<>"",D55>C55,J55<G55),"Plan over budget",IF(J55=G55,"All given ✓",IF(H55<G55,"Shopping",IF(I55<G55,"To wrap","Ready to give")))))))
A57: TOTAL | B57: =COUNTA(A6:A55)&" people" | C57: =SUM(C6:C55) | D57: =SUM(D6:D55) | E57: =SUM(E6:E55) | F57: =SUM(F6:F55) | G57: =SUM(G6:G55) | H57: =SUM(H6:H55) | I57: =SUM(I6:I55) | J57: =SUM(J6:J55)

Sheet Gift Tracker
A1: Gift Tracker
A2: One row per gift. Pick the person, add the price, then mark Bought, Wrapped and Given.
A4: Person | B4: Gift | C4: Store / link | D4: Price | E4: Bought? | F4: Wrapped? | G4: Given? | H4: Notes / order #
A5: Mom | B5: Cozy cardigan | C5: Department store | D5: 54 | E5: Yes | F5: Yes
A6: Mom | B6: Cookbook | C6: Bookshop | D6: 28.5 | E6: Yes | F6: No
A7: Mom | B7: Hand cream set | C7: Pharmacy | D7: 18 | E7: No | F7: No
A8: Dad | B8: Coffee grinder | C8: Online | D8: 69.99 | E8: Yes | F8: Yes
A9: Dad | B9: Wool socks | C9: Outdoor shop | D9: 16 | E9: Yes | F9: Yes
A10: Dad | B10: Puzzle, 1000 pieces | C10: Toy store | D10: 22 | E10: No | F10: No
A11: Emma | B11: Art set | C11: Craft store | D11: 34.99 | E11: Yes | F11: Yes
A12: Emma | B12: Ice skates | C12: Sports store | D12: 79 | E12: Yes | F12: No | H12: Order #48213, arrives Dec 9
A13: Emma | B13: Chapter book series | C13: Bookshop | D13: 24 | E13: No | F13: No
A14: Emma | B14: Pajamas | C14: Online | D14: 19.5 | E14: Yes | F14: Yes
A15: Leo | B15: Building blocks set | C15: Toy store | D15: 59.99 | E15: Yes | F15: Yes
A16: Leo | B16: Rain boots | C16: Shoe store | D16: 32 | E16: Yes | F16: No
A17: Leo | B17: Picture books (2) | C17: Bookshop | D17: 21 | E17: Yes | F17: Yes
A18: Leo | B18: Remote-control car | C18: Online | D18: 44 | E18: Yes | F18: No | H18: Hide in garage
A19: Grandma Jo | B19: Photo calendar | C19: Print shop | D19: 29 | E19: Yes | F19: Yes
A20: Grandma Jo | B20: Tea sampler | C20: Tea shop | D20: 24 | E20: Yes | F20: Yes
A21: Grandma Jo | B21: Scarf | C21: Market | D21: 22 | E21: Yes | F21: No
A22: Aunt Sara | B22: Candle | C22: Gift shop | D22: 26 | E22: Yes | F22: Yes
A23: Sam (Secret Santa) | B23: Desk plant | C23: Garden center | D23: 22 | E23: Yes | F23: Yes | G23: Yes | H23: Limit $25
A24: Ms. Rivera (teacher) | B24: Gift card + card from Leo | C24: Coffee shop | D24: 20 | E24: Yes | F24: Yes | G24: Yes
A25: Neighbors | B25: Homemade cookie tins (3) | C25: Baking | D25: 18 | E25: Yes | F25: No
A26: Best friend Kim | B26: Concert tickets (half) | C26: Online | D26: 45 | E26: Yes | F26: Yes
A27: Best friend Kim | B27: Card game | C27: Game shop | D27: 15 | E27: No | F27: No

Sheet Expense Log
A1: Holiday Expense Log
A2: Everything that isn't a gift: food, decorations, cards, travel... Gifts go in the Gift Tracker.
A4: Date | B4: What | C4: Category | D4: Amount | E4: Paid with | F4: Running total
A5: 46328 | B5: Advent candles + garland | C5: Decorations | D5: 34.5 | E5: Debit card | F5: =IF(D5="","",SUM($D$5:D5))
A6: 46334 | B6: Christmas cards (box of 40) | C6: Cards & postage | D6: 18.99 | E6: Cash | F6: =IF(D6="","",SUM($D$5:D6))
A7: 46334 | B7: Stamps | C7: Cards & postage | D7: 27.2 | E7: Cash | F7: =IF(D7="","",SUM($D$5:D7))
A8: 46341 | B8: Wrapping paper, tape, ribbon | C8: Wrapping & tags | D8: 24.75 | E8: Debit card | F8: =IF(D8="","",SUM($D$5:D8))
A9: 46348 | B9: Train tickets to Grandma's | C9: Travel | D9: 136 | E9: Credit card | F9: =IF(D9="","",SUM($D$5:D9))
A10: 46355 | B10: Tree | C10: Decorations | D10: 65 | E10: Cash | F10: =IF(D10="","",SUM($D$5:D10))
A11: 46359 | B11: Baking supplies | C11: Food & treats | D11: 42.3 | E11: Debit card | F11: =IF(D11="","",SUM($D$5:D11))
A12: 46362 | B12: Food bank donation | C12: Charity & giving | D12: 40 | E12: Debit card | F12: =IF(D12="","",SUM($D$5:D12))
A13: 46366 | B13: Holiday party snacks | C13: Parties & hosting | D13: 58.4 | E13: Credit card | F13: =IF(D13="","",SUM($D$5:D13))
A14: 46369 | B14: Ice rink tickets | C14: Kids' activities | D14: 32 | E14: Debit card | F14: =IF(D14="","",SUM($D$5:D14))
A15: 46370 | B15: Matching sweaters | C15: Outfits | D15: 72 | E15: Credit card | F15: =IF(D15="","",SUM($D$5:D15))
F16: =IF(D16="","",SUM($D$5:D16))
F17: =IF(D17="","",SUM($D$5:D17))
F18: =IF(D18="","",SUM($D$5:D18))
F19: =IF(D19="","",SUM($D$5:D19))
F20: =IF(D20="","",SUM($D$5:D20))
F21: =IF(D21="","",SUM($D$5:D21))
F22: =IF(D22="","",SUM($D$5:D22))
F23: =IF(D23="","",SUM($D$5:D23))
F24: =IF(D24="","",SUM($D$5:D24))
F25: =IF(D25="","",SUM($D$5:D25))
F26: =IF(D26="","",SUM($D$5:D26))
F27: =IF(D27="","",SUM($D$5:D27))
... F404: =IF(D404="","",SUM($D$5:D404))

Sheet Savings
A1: Christmas Savings Plan
A2: Set a goal and a start date; it works out how much to put aside each week.
A4: Savings goal | B4: 600 | C4: Saved so far | D4: =SUM(D10:D61)
A5: Start saving on | B5: 46272 | C5: Still to save | D5: =IF(B4="","",MAX(0,B4-D4))
A6: Christmas | B6: =IF(B5="","",DATE(YEAR(B5)+IF(B5>DATE(YEAR(B5),12,25),1,0),12,25)) | C6: % of goal | D6: =IF(N(B4)=0,"",D4/B4) | E6: =IF(D6="","",REPT("█",ROUND(MIN(1,MAX(0,D6))*20,0))&REPT("░",20-ROUND(MIN(1,MAX(0,D6))*20,0)))
A7: Weeks to save | B7: =IF(B6="","",MAX(1,ROUNDUP((B6-B5)/7,0)))
A8: Save each week | B8: =IF(OR(B4="",B7=""),"",B4/B7)
A9: Week | B9: Week of | C9: Plan | D9: Saved | E9: Total saved | F9: On track?
A10: =IF(OR($B$7="",1>$B$7),"",1) | B10: =IF(A10="","",$B$5+7*(A10-1)) | C10: =IF(A10="","",$B$8) | D10: 40 | E10: =IF(A10="","",SUM($D$10:D10)) | F10: =IF(OR(A10="",D10=""),"",IF(E10+0.005>=$B$8*A10,"On track ✓","Behind by "&TEXT($B$8*A10-E10,"$#,##0.00")))
A11: =IF(OR($B$7="",2>$B$7),"",2) | B11: =IF(A11="","",$B$5+7*(A11-1)) | C11: =IF(A11="","",$B$8) | D11: 40 | E11: =IF(A11="","",SUM($D$10:D11)) | F11: =IF(OR(A11="",D11=""),"",IF(E11+0.005>=$B$8*A11,"On track ✓","Behind by "&TEXT($B$8*A11-E11,"$#,##0.00")))
A12: =IF(OR($B$7="",3>$B$7),"",3) | B12: =IF(A12="","",$B$5+7*(A12-1)) | C12: =IF(A12="","",$B$8) | D12: 35 | E12: =IF(A12="","",SUM($D$10:D12)) | F12: =IF(OR(A12="",D12=""),"",IF(E12+0.005>=$B$8*A12,"On track ✓","Behind by "&TEXT($B$8*A12-E12,"$#,##0.00")))
A13: =IF(OR($B$7="",4>$B$7),"",4) | B13: =IF(A13="","",$B$5+7*(A13-1)) | C13: =IF(A13="","",$B$8) | D13: 40 | E13: =IF(A13="","",SUM($D$10:D13)) | F13: =IF(OR(A13="",D13=""),"",IF(E13+0.005>=$B$8*A13,"On track ✓","Behind by "&TEXT($B$8*A13-E13,"$#,##0.00")))
A14: =IF(OR($B$7="",5>$B$7),"",5) | B14: =IF(A14="","",$B$5+7*(A14-1)) | C14: =IF(A14="","",$B$8) | D14: 20 | E14: =IF(A14="","",SUM($D$10:D14)) | F14: =IF(OR(A14="",D14=""),"",IF(E14+0.005>=$B$8*A14,"On track ✓","Behind by "&TEXT($B$8*A14-E14,"$#,##0.00")))
A15: =IF(OR($B$7="",6>$B$7),"",6) | B15: =IF(A15="","",$B$5+7*(A15-1)) | C15: =IF(A15="","",$B$8) | D15: 40 | E15: =IF(A15="","",SUM($D$10:D15)) | F15: =IF(OR(A15="",D15=""),"",IF(E15+0.005>=$B$8*A15,"On track ✓","Behind by "&TEXT($B$8*A15-E15,"$#,##0.00")))
A16: =IF(OR($B$7="",7>$B$7),"",7) | B16: =IF(A16="","",$B$5+7*(A16-1)) | C16: =IF(A16="","",$B$8) | D16: 40 | E16: =IF(A16="","",SUM($D$10:D16)) | F16: =IF(OR(A16="",D16=""),"",IF(E16+0.005>=$B$8*A16,"On track ✓","Behind by "&TEXT($B$8*A16-E16,"$#,##0.00")))
A17: =IF(OR($B$7="",8>$B$7),"",8) | B17: =IF(A17="","",$B$5+7*(A17-1)) | C17: =IF(A17="","",$B$8) | D17: 30 | E17: =IF(A17="","",SUM($D$10:D17)) | F17: =IF(OR(A17="",D17=""),"",IF(E17+0.005>=$B$8*A17,"On track ✓","Behind by "&TEXT($B$8*A17-E17,"$#,##0.00")))
A18: =IF(OR($B$7="",9>$B$7),"",9) | B18: =IF(A18="","",$B$5+7*(A18-1)) | C18: =IF(A18="","",$B$8) | E18: =IF(A18="","",SUM($D$10:D18)) | F18: =IF(OR(A18="",D18=""),"",IF(E18+0.005>=$B$8*A18,"On track ✓","Behind by "&TEXT($B$8*A18-E18,"$#,##0.00")))
A19: =IF(OR($B$7="",10>$B$7),"",10) | B19: =IF(A19="","",$B$5+7*(A19-1)) | C19: =IF(A19="","",$B$8) | E19: =IF(A19="","",SUM($D$10:D19)) | F19: =IF(OR(A19="",D19=""),"",IF(E19+0.005>=$B$8*A19,"On track ✓","Behind by "&TEXT($B$8*A19-E19,"$#,##0.00")))
A20: =IF(OR($B$7="",11>$B$7),"",11) | B20: =IF(A20="","",$B$5+7*(A20-1)) | C20: =IF(A20="","",$B$8) | E20: =IF(A20="","",SUM($D$10:D20)) | F20: =IF(OR(A20="",D20=""),"",IF(E20+0.005>=$B$8*A20,"On track ✓","Behind by "&TEXT($B$8*A20-E20,"$#,##0.00")))
A21: =IF(OR($B$7="",12>$B$7),"",12) | B21: =IF(A21="","",$B$5+7*(A21-1)) | C21: =IF(A21="","",$B$8) | E21: =IF(A21="","",SUM($D$10:D21)) | F21: =IF(OR(A21="",D21=""),"",IF(E21+0.005>=$B$8*A21,"On track ✓","Behind by "&TEXT($B$8*A21-E21,"$#,##0.00")))
A22: =IF(OR($B$7="",13>$B$7),"",13) | B22: =IF(A22="","",$B$5+7*(A22-1)) | C22: =IF(A22="","",$B$8) | E22: =IF(A22="","",SUM($D$10:D22)) | F22: =IF(OR(A22="",D22=""),"",IF(E22+0.005>=$B$8*A22,"On track ✓","Behind by "&TEXT($B$8*A22-E22,"$#,##0.00")))
A23: =IF(OR($B$7="",14>$B$7),"",14) | B23: =IF(A23="","",$B$5+7*(A23-1)) | C23: =IF(A23="","",$B$8) | E23: =IF(A23="","",SUM($D$10:D23)) | F23: =IF(OR(A23="",D23=""),"",IF(E23+0.005>=$B$8*A23,"On track ✓","Behind by "&TEXT($B$8*A23-E23,"$#,##0.00")))
A24: =IF(OR($B$7="",15>$B$7),"",15) | B24: =IF(A24="","",$B$5+7*(A24-1)) | C24: =IF(A24="","",$B$8) | E24: =IF(A24="","",SUM($D$10:D24)) | F24: =IF(OR(A24="",D24=""),"",IF(E24+0.005>=$B$8*A24,"On track ✓","Behind by "&TEXT($B$8*A24-E24,"$#,##0.00")))
A25: =IF(OR($B$7="",16>$B$7),"",16) | B25: =IF(A25="","",$B$5+7*(A25-1)) | C25: =IF(A25="","",$B$8) | E25: =IF(A25="","",SUM($D$10:D25)) | F25: =IF(OR(A25="",D25=""),"",IF(E25+0.005>=$B$8*A25,"On track ✓","Behind by "&TEXT($B$8*A25-E25,"$#,##0.00")))
A26: =IF(OR($B$7="",17>$B$7),"",17) | B26: =IF(A26="","",$B$5+7*(A26-1)) | C26: =IF(A26="","",$B$8) | E26: =IF(A26="","",SUM($D$10:D26)) | F26: =IF(OR(A26="",D26=""),"",IF(E26+0.005>=$B$8*A26,"On track ✓","Behind by "&TEXT($B$8*A26-E26,"$#,##0.00")))
A27: =IF(OR($B$7="",18>$B$7),"",18) | B27: =IF(A27="","",$B$5+7*(A27-1)) | C27: =IF(A27="","",$B$8) | E27: =IF(A27="","",SUM($D$10:D27)) | F27: =IF(OR(A27="",D27=""),"",IF(E27+0.005>=$B$8*A27,"On track ✓","Behind by "&TEXT($B$8*A27-E27,"$#,##0.00")))
A28: =IF(OR($B$7="",19>$B$7),"",19) | B28: =IF(A28="","",$B$5+7*(A28-1)) | C28: =IF(A28="","",$B$8) | E28: =IF(A28="","",SUM($D$10:D28)) | F28: =IF(OR(A28="",D28=""),"",IF(E28+0.005>=$B$8*A28,"On track ✓","Behind by "&TEXT($B$8*A28-E28,"$#,##0.00")))
A29: =IF(OR($B$7="",20>$B$7),"",20) | B29: =IF(A29="","",$B$5+7*(A29-1)) | C29: =IF(A29="","",$B$8) | E29: =IF(A29="","",SUM($D$10:D29)) | F29: =IF(OR(A29="",D29=""),"",IF(E29+0.005>=$B$8*A29,"On track ✓","Behind by "&TEXT($B$8*A29-E29,"$#,##0.00")))
A30: =IF(OR($B$7="",21>$B$7),"",21) | B30: =IF(A30="","",$B$5+7*(A30-1)) | C30: =IF(A30="","",$B$8) | E30: =IF(A30="","",SUM($D$10:D30)) | F30: =IF(OR(A30="",D30=""),"",IF(E30+0.005>=$B$8*A30,"On track ✓","Behind by "&TEXT($B$8*A30-E30,"$#,##0.00")))
A31: =IF(OR($B$7="",22>$B$7),"",22) | B31: =IF(A31="","",$B$5+7*(A31-1)) | C31: =IF(A31="","",$B$8) | E31: =IF(A31="","",SUM($D$10:D31)) | F31: =IF(OR(A31="",D31=""),"",IF(E31+0.005>=$B$8*A31,"On track ✓","Behind by "&TEXT($B$8*A31-E31,"$#,##0.00")))
A32: =IF(OR($B$7="",23>$B$7),"",23) | B32: =IF(A32="","",$B$5+7*(A32-1)) | C32: =IF(A32="","",$B$8) | E32: =IF(A32="","",SUM($D$10:D32)) | F32: =IF(OR(A32="",D32=""),"",IF(E32+0.005>=$B$8*A32,"On track ✓","Behind by "&TEXT($B$8*A32-E32,"$#,##0.00")))
A33: =IF(OR($B$7="",24>$B$7),"",24) | B33: =IF(A33="","",$B$5+7*(A33-1)) | C33: =IF(A33="","",$B$8) | E33: =IF(A33="","",SUM($D$10:D33)) | F33: =IF(OR(A33="",D33=""),"",IF(E33+0.005>=$B$8*A33,"On track ✓","Behind by "&TEXT($B$8*A33-E33,"$#,##0.00")))
A34: =IF(OR($B$7="",25>$B$7),"",25) | B34: =IF(A34="","",$B$5+7*(A34-1)) | C34: =IF(A34="","",$B$8) | E34: =IF(A34="","",SUM($D$10:D34)) | F34: =IF(OR(A34="",D34=""),"",IF(E34+0.005>=$B$8*A34,"On track ✓","Behind by "&TEXT($B$8*A34-E34,"$#,##0.00")))
A35: =IF(OR($B$7="",26>$B$7),"",26) | B35: =IF(A35="","",$B$5+7*(A35-1)) | C35: =IF(A35="","",$B$8) | E35: =IF(A35="","",SUM($D$10:D35)) | F35: =IF(OR(A35="",D35=""),"",IF(E35+0.005>=$B$8*A35,"On track ✓","Behind by "&TEXT($B$8*A35-E35,"$#,##0.00")))
A36: =IF(OR($B$7="",27>$B$7),"",27) | B36: =IF(A36="","",$B$5+7*(A36-1)) | C36: =IF(A36="","",$B$8) | E36: =IF(A36="","",SUM($D$10:D36)) | F36: =IF(OR(A36="",D36=""),"",IF(E36+0.005>=$B$8*A36,"On track ✓","Behind by "&TEXT($B$8*A36-E36,"$#,##0.00")))
A37: =IF(OR($B$7="",28>$B$7),"",28) | B37: =IF(A37="","",$B$5+7*(A37-1)) | C37: =IF(A37="","",$B$8) | E37: =IF(A37="","",SUM($D$10:D37)) | F37: =IF(OR(A37="",D37=""),"",IF(E37+0.005>=$B$8*A37,"On track ✓","Behind by "&TEXT($B$8*A37-E37,"$#,##0.00")))
A38: =IF(OR($B$7="",29>$B$7),"",29) | B38: =IF(A38="","",$B$5+7*(A38-1)) | C38: =IF(A38="","",$B$8) | E38: =IF(A38="","",SUM($D$10:D38)) | F38: =IF(OR(A38="",D38=""),"",IF(E38+0.005>=$B$8*A38,"On track ✓","Behind by "&TEXT($B$8*A38-E38,"$#,##0.00")))
A39: =IF(OR($B$7="",30>$B$7),"",30) | B39: =IF(A39="","",$B$5+7*(A39-1)) | C39: =IF(A39="","",$B$8) | E39: =IF(A39="","",SUM($D$10:D39)) | F39: =IF(OR(A39="",D39=""),"",IF(E39+0.005>=$B$8*A39,"On track ✓","Behind by "&TEXT($B$8*A39-E39,"$#,##0.00")))
A40: =IF(OR($B$7="",31>$B$7),"",31) | B40: =IF(A40="","",$B$5+7*(A40-1)) | C40: =IF(A40="","",$B$8) | E40: =IF(A40="","",SUM($D$10:D40)) | F40: =IF(OR(A40="",D40=""),"",IF(E40+0.005>=$B$8*A40,"On track ✓","Behind by "&TEXT($B$8*A40-E40,"$#,##0.00")))
A41: =IF(OR($B$7="",32>$B$7),"",32) | B41: =IF(A41="","",$B$5+7*(A41-1)) | C41: =IF(A41="","",$B$8) | E41: =IF(A41="","",SUM($D$10:D41)) | F41: =IF(OR(A41="",D41=""),"",IF(E41+0.005>=$B$8*A41,"On track ✓","Behind by "&TEXT($B$8*A41-E41,"$#,##0.00")))
...
